Workbook

Sheet Sheet1
A1: Date | B1: WindSpeed | C1: RH | D1: Precipitation | E1: Maxtemp | F1: Mintemp
A2: 2024-01-01 | B2: 3.4 | C2: 68 | D2: ='C0K430-2024-Precipitation-day'!B3 -> 0 | E2: 21.1 | F2: 14.6
A3: 2024-01-02 | B3: 2 | C3: 77 | D3: ='C0K430-2024-Precipitation-day'!B4 -> 0 | E3: 22.6 | F3: 13.8
A4: 2024-01-03 | B4: 3.7 | C4: 78 | D4: ='C0K430-2024-Precipitation-day'!B5 -> 0 | E4: 20.5 | F4: 13.2
A5: 2024-01-04 | B5: 1.7 | C5: 70 | D5: ='C0K430-2024-Precipitation-day'!B6 -> 0 | E5: 20.8 | F5: 11.2
A6: 2024-01-05 | B6: 1.5 | C6: 84 | D6: ='C0K430-2024-Precipitation-day'!B7 -> 0 | E6: 21.5 | F6: 14.1
A7: 2024-01-06 | B7: 1.8 | C7: 82 | D7: ='C0K430-2024-Precipitation-day'!B8 -> 0 | E7: 22.7 | F7: 13.4
A8: 2024-01-07 | B8: 3.1 | C8: 70 | D8: ='C0K430-2024-Precipitation-day'!B9 -> 0 | E8: 22 | F8: 14.9
A9: 2024-01-08 | B9: 2.3 | C9: 76 | D9: ='C0K430-2024-Precipitation-day'!B10 -> 0 | E9: 23.3 | F9: 14.5
A10: 2024-01-09 | B10: 2.6 | C10: 87 | D10: ='C0K430-2024-Precipitation-day'!B11 -> 0 | E10: 22.8 | F10: 16.5
A11: 2024-01-10 | B11: 4.1 | C11: 67 | D11: ='C0K430-2024-Precipitation-day'!B12 -> 0 | E11: 21.6 | F11: 15.2
A12: 2024-01-11 | B12: 2.5 | C12: 59 | D12: ='C0K430-2024-Precipitation-day'!B13 -> 0 | E12: 21.1 | F12: 11.6
A13: 2024-01-12 | B13: 1.5 | C13: 73 | D13: ='C0K430-2024-Precipitation-day'!B14 -> 0 | E13: 23.7 | F13: 11.5
... A32: 2024-01-31 | B32: 1.8 | C32: 84 | D32: ='C0K430-2024-Precipitation-day'!B33 -> 0 | E32: 28 | F32: 17.2
A33: 2024-02-01 | B33: 1.2 | C33: 82 | D33: ='C0K430-2024-Precipitation-day'!C3 -> 0 | E33: 28.3 | F33: 16.3
A34: 2024-02-02 | B34: 2.3 | C34: 89 | D34: ='C0K430-2024-Precipitation-day'!C4 -> 0 | E34: 23.3 | F34: 17.1
A35: 2024-02-03 | B35: 2.1 | C35: 89 | D35: ='C0K430-2024-Precipitation-day'!C5 -> 0 | E35: 23.1 | F35: 17.2
A36: 2024-02-04 | B36: 2.1 | C36: 92 | D36: ='C0K430-2024-Precipitation-day'!C6 -> 0 | E36: 24.7 | F36: 15.4
A37: 2024-02-05 | B37: 2.8 | C37: 81 | D37: ='C0K430-2024-Precipitation-day'!C7 -> 0 | E37: 25.3 | F37: 15.4
A38: 2024-02-06 | B38: 2.2 | C38: 83 | D38: ='C0K430-2024-Precipitation-day'!C8 -> 0 | E38: 21.7 | F38: 16.5
A39: 2024-02-07 | B39: 3.6 | C39: 89 | D39: ='C0K430-2024-Precipitation-day'!C9 -> 4 | E39: 0 | F39: 0
A40: 2024-02-08 | B40: 3.5 | C40: 85 | D40: ='C0K430-2024-Precipitation-day'!C10 -> 6.5 | E40: 18.1 | F40: 12.8
A41: 2024-02-09 | B41: 4 | C41: 82 | D41: ='C0K430-2024-Precipitation-day'!C11 -> 8 | E41: 16.5 | F41: 11.6
A42: 2024-02-10 | B42: 3.2 | C42: 68 | D42: ='C0K430-2024-Precipitation-day'!C12 -> 0 | E42: 18.9 | F42: 11.8
A43: 2024-02-11 | B43: 2.7 | C43: 60 | D43: ='C0K430-2024-Precipitation-day'!C13 -> 0 | E43: 21.5 | F43: 10.2
A44: 2024-02-12 | B44: 1.4 | C44: 71 | D44: ='C0K430-2024-Precipitation-day'!C14 -> 0 | E44: 22.1 | F44: 9.8
... A61: 2024-02-29 | B61: 2.2 | C61: 82 | D61: ='C0K430-2024-Precipitation-day'!C31 -> 0 | E61: 27.8 | F61: 16
A62: 2024-03-01 | B62: 4.7 | C62: 75 | D62: ='C0K430-2024-Precipitation-day'!D3 -> 0 | E62: 19.2 | F62: 12.1
A63: 2024-03-02 | B63: 3.2 | C63: 77 | D63: ='C0K430-2024-Precipitation-day'!D4 -> 0 | E63: 15.3 | F63: 11.4
A64: 2024-03-03 | B64: 2.2 | C64: 79 | D64: ='C0K430-2024-Precipitation-day'!D5 -> 0 | E64: 22 | F64: 12
A65: 2024-03-04 | B65: 1.4 | C65: 83 | D65: ='C0K430-2024-Precipitation-day'!D6 -> 0 | E65: 25.6 | F65: 15.4
A66: 2024-03-05 | B66: 3.8 | C66: 70 | D66: ='C0K430-2024-Precipitation-day'!D7 -> 0 | E66: 30.3 | F66: 18.8
A67: 2024-03-06 | B67: 2.8 | C67: 76 | D67: ='C0K430-2024-Precipitation-day'!D8 -> 0 | E67: 28.5 | F67: 16.1
A68: 2024-03-07 | B68: 3.8 | C68: 78 | D68: ='C0K430-2024-Precipitation-day'!D9 -> 0 | E68: 18.6 | F68: 14.9
A69: 2024-03-08 | B69: 3.7 | C69: 56 | D69: ='C0K430-2024-Precipitation-day'!D10 -> 0 | E69: 20.6 | F69: 14
A70: 2024-03-09 | B70: 3 | C70: 56 | D70: ='C0K430-2024-Precipitation-day'!D11 -> 0 | E70: 17.5 | F70: 11.7
A71: 2024-03-10 | B71: 2.4 | C71: 75 | D71: ='C0K430-2024-Precipitation-day'!D12 -> 0 | E71: 20.4 | F71: 13.8
A72: 2024-03-11 | B72: 1.7 | C72: 93 | D72: ='C0K430-2024-Precipitation-day'!D13 -> 2 | E72: 19.3 | F72: 16.4
A73: 2024-03-12 | B73: 3.1 | C73: 73 | D73: ='C0K430-2024-Precipitation-day'!D14 -> 0.5 | E73: 23 | F73: 14.9
... A92: 2024-03-31 | B92: 3.5 | C92: 82 | D92: ='C0K430-2024-Precipitation-day'!D33 -> 0.5 | E92: 30.1 | F92: 22.9
...

Sheet C0K430-2024-RelativeHumidity-da
A2: 日/月 | B2: 1 | C2: 2 | D2: 3 | E2: 4 | F2: 5 | G2: 6 | H2: 7 | I2: 8 | J2: 9 | K2: 10 | L2: 11 | M2: 12
A3: 1 | B3: 68 | C3: 82 | D3: 75 | E3: 88 | F3: 85 | G3: 84 | H3: 74 | I3: 70 | J3: 69 | K3: 82 | L3: 88 | M3: 75
A4: 2 | B4: 77 | C4: 89 | D4: 77 | E4: 84 | F4: 83 | G4: 95 | H4: 75 | I4: 70 | J4: 70 | K4: 75 | L4: 74 | M4: 85
A5: 3 | B5: 78 | C5: 89 | D5: 79 | E5: 80 | F5: 82 | G5: 76 | H5: 73 | I5: 69 | J5: 69 | K5: 73 | L5: 77 | M5: 82
A6: 4 | B6: 70 | C6: 92 | D6: 83 | E6: 79 | F6: 85 | G6: 81 | H6: 76 | I6: 65 | J6: 66 | K6: 77 | L6: 74 | M6: 71
A7: 5 | B7: 84 | C7: 81 | D7: 70 | E7: 82 | F7: 91 | G7: 89 | H7: 77 | I7: 67 | J7: 75 | K7: 80 | L7: 70 | M7: 71
A8: 6 | B8: 82 | C8: 83 | D8: 76 | E8: 80 | F8: 84 | G8: 90 | H8: 77 | I8: 73 | J8: 75 | K8: 78 | L8: 58 | M8: 74
A9: 7 | B9: 70 | C9: 89 | D9: 78 | E9: 84 | F9: 84 | G9: 86 | H9: 75 | I9: 66 | J9: 74 | K9: 74 | L9: 65 | M9: 74
A10: 8 | B10: 76 | C10: 85 | D10: 56 | E10: 87 | F10: 79 | G10: 83 | H10: 79 | I10: 73 | J10: 77 | K10: 72 | L10: 77 | M10: 67
A11: 9 | B11: 87 | C11: 82 | D11: 56 | E11: 78 | F11: 69 | G11: 84 | H11: 72 | I11: 73 | J11: 80 | K11: 68 | L11: 83 | M11: 69
A12: 10 | B12: 67 | C12: 68 | D12: 75 | E12: 82 | F12: 78 | G12: 85 | H12: 76 | I12: 76 | J12: 75 | K12: 65 | L12: 84 | M12: 79
A13: 11 | B13: 59 | C13: 60 | D13: 93 | E13: 88 | F13: 66 | G13: 86 | H13: 76 | I13: 69 | J13: 72 | K13: 63 | L13: 78 | M13: 79
A14: 12 | B14: 73 | C14: 71 | D14: 73 | E14: 80 | F14: 70 | G14: 84 | H14: 71 | I14: 66 | J14: 76 | K14: 67 | L14: 87 | M14: 72
... A31: 29 | B31: 86 | C31: 82 | D31: 80 | E31: 82 | F31: 85 | G31: 73 | H31: 77 | I31: 69 | J31: 67 | K31: 70 | L31: 52 | M31: 63
A32: 30 | B32: 89 | C32: -- | D32: 83 | E32: 81 | F32: 83 | G32: 74 | H32: 73 | I32: 67 | J32: 72 | K32: 70 | L32: 68 | M32: 81
A33: 31 | B33: 84 | C33: -- | D33: 82 | E33: -- | F33: 77 | G33: -- | H33: 72 | I33: 67 | J33: -- | K33: 83 | L33: -- | M33: 63
A34: 平均 | B34: 78 | C34: 79 | D34: 76 | E34: 83 | F34: 81 | G34: 81 | H34: 76 | I34: 71 | J34: 74 | K34: 75 | L34: 75 | M34: 72

Sheet C0K430-2024-Precipitation-day
A2: 日/月 | B2: 1 | C2: 2 | D2: 3 | E2: 4 | F2: 5 | G2: 6 | H2: 7 | I2: 8 | J2: 9 | K2: 10 | L2: 11 | M2: 12
A3: 1 | B3: 0 | C3: 0 | D3: 0 | E3: 33 | F3: 27 | G3: 1.5 | H3: 0 | I3: 0 | J3: 0 | K3: 1.5 | L3: 32 | M3: 0
A4: 2 | B4: 0 | C4: 0 | D4: 0 | E4: 0 | F4: 0.5 | G4: 52 | H4: 0 | I4: 0 | J4: 0 | K4: 2 | L4: 0 | M4: 0
A5: 3 | B5: 0 | C5: 0 | D5: 0 | E5: 0 | F5: 0 | G5: 0 | H5: 3 | I5: 0 | J5: 0 | K5: 0 | L5: 0 | M5: 0
A6: 4 | B6: 0 | C6: 0 | D6: 0 | E6: 0 | F6: 0 | G6: 6 | H6: 0 | I6: 0 | J6: 0 | K6: 0 | L6: 0 | M6: 0
A7: 5 | B7: 0 | C7: 0 | D7: 0 | E7: 0 | F7: 4 | G7: 0 | H7: 0 | I7: 0 | J7: 20.5 | K7: 0 | L7: 0 | M7: 0
A8: 6 | B8: 0 | C8: 0 | D8: 0 | E8: 0 | F8: 0 | G8: 4.5 | H8: 2.5 | I8: 0 | J8: 0 | K8: 0 | L8: 0 | M8: 0
A9: 7 | B9: 0 | C9: 4 | D9: 0 | E9: 0 | F9: 0 | G9: 0 | H9: 9 | I9: 0 | J9: 4 | K9: 0 | L9: 0 | M9: 0
A10: 8 | B10: 0 | C10: 6.5 | D10: 0 | E10: 0 | F10: 0 | G10: 0 | H10: 1.5 | I10: 1.5 | J10: 12 | K10: 0 | L10: 0 | M10: 0
A11: 9 | B11: 0 | C11: 8 | D11: 0 | E11: 0 | F11: 0 | G11: 0 | H11: 0 | I11: 1 | J11: 3 | K11: 0 | L11: 0 | M11: 0
A12: 10 | B12: 0 | C12: 0 | D12: 0 | E12: 0 | F12: 0 | G12: 8.5 | H12: 0 | I12: 0.5 | J12: 0 | K12: 0 | L12: 0 | M12: 0
A13: 11 | B13: 0 | C13: 0 | D13: 2 | E13: 0 | F13: 0 | G13: 19 | H13: 0 | I13: 0 | J13: 0 | K13: 0 | L13: 0 | M13: 0
A14: 12 | B14: 0 | C14: 0 | D14: 0.5 | E14: 0 | F14: 0 | G14: 1.5 | H14: 0 | I14: 0 | J14: 0 | K14: 0 | L14: 0 | M14: 0
... A31: 29 | B31: 0.5 | C31: 0 | D31: 0 | E31: 0 | F31: 2 | G31: 2 | H31: 0 | I31: 0 | J31: 0 | K31: 0 | L31: 0 | M31: 0
A32: 30 | B32: 0 | C32: -- | D32: 0 | E32: 0.5 | F32: 4 | G32: 0 | H32: 0 | I32: 0 | J32: 0 | K32: 0 | L32: 0 | M32: 0
A33: 31 | B33: 0 | C33: -- | D33: 0.5 | E33: -- | F33: 5 | G33: -- | H33: 0 | I33: 0 | J33: -- | K33: 13 | L33: -- | M33: 0
A34: 總和 | B34: 2.5 | C34: 18.5 | D34: 3.5 | E34: 134.5 | F34: 143.5 | G34: 111 | H34: 633 | I34: 107.5 | J34: 245 | K34: 16.5 | L34: 35.5 | M34: 25
